<?xml version="1.0" ?>
<robot name="slamtec" xmlns:xacro="http://www.ros.org/wiki/xacro">

  <!-- <xacro:property name="package_name" value="kcare_description"/>
  <xacro:property name="mesh_path" value="package://${package_name}/meshes"/>
  <xacro:include filename="$(find kcare_description)/robots/common/link.xacro"/> -->


  <xacro:property name="mesh_path" value="package://kcare_description/meshes/"/>

  <xacro:common_link
    name="slam_base"
    inertial_origin="-0.004242067006968334 0.0005565721742923574 0.176282566938588"
    mass="42.44816908546966"
    ixx="1.368829" iyy="1.544543" izz="1.587721" ixy="0.00047" iyz="0.00375" ixz="-0.000201"
    mesh_file="${mesh_path}slamware/base_link.stl"
  />

  <xacro:common_link
    name="left_wheel"
    inertial_origin="-0.001865 0.052015 -0.010160"
    mass="3.867230"
    ixx="0.016843" iyy="0.009476" izz="0.009476" ixy="-0.000000" iyz="0.000000" ixz="0.000000"
    mesh_file="${mesh_path}slamware/slam_wheel.stl"
    material="black"
  />

  <xacro:common_link
    name="right_wheel"
    inertial_origin="-0.001865 0.052015 -0.010160"
    mass="3.867230"
    ixx="0.016843" iyy="0.009476" izz="0.009476" ixy="-0.000000" iyz="0.000000" ixz="0.000000"
    mesh_file="${mesh_path}slamware/slam_wheel.stl"
    material="black"
  />

  <xacro:common_link
    name="lf_caster"
    inertial_origin="-0.018022 -0.000120 -0.048838"
    mass="1.177702"
    ixx="0.001147" iyy="0.001298" izz="0.000735" ixy="-0.000001" iyz="-0.000002" ixz="-0.000319"
    mesh_file="${mesh_path}slamware/caster.stl"
    material="black"
  />

  <xacro:common_link
    name="rf_caster"
    inertial_origin="-0.018022 -0.000120 -0.048838"
    mass="1.177702"
    ixx="0.001147" iyy="0.001298" izz="0.000735" ixy="-0.000001" iyz="-0.000002" ixz="-0.000319"
    mesh_file="${mesh_path}slamware/caster.stl"
    material="black"
  />

  <xacro:common_link
    name="lb_caster"
    inertial_origin="-0.018022 -0.000120 -0.048838"
    mass="1.177702"
    ixx="0.001147" iyy="0.001298" izz="0.000735" ixy="-0.000001" iyz="-0.000002" ixz="-0.000319"
    mesh_file="${mesh_path}slamware/caster.stl"
    material="black"
  />

  <xacro:common_link
    name="rb_caster"
    inertial_origin="-0.018022 -0.000120 -0.048838"
    mass="1.177702"
    ixx="0.001147" iyy="0.001298" izz="0.000735" ixy="-0.000001" iyz="-0.000002" ixz="-0.000319"
    mesh_file="${mesh_path}slamware/caster.stl"
    material="black"
  />

  <joint name="left_wheel_joint" type="continuous">
    <origin xyz="0.0 0.16885 0.0" rpy="0 0 -1.5708"/>
    <parent link="slam_base"/>
    <child link="left_wheel"/>
    <axis xyz="-1.0 0.0 0.0"/>
  </joint>

  <joint name="right_wheel_joint" type="continuous">
    <origin xyz="0.0 -0.16885 0.0" rpy="0 0 1.5708"/>
    <parent link="slam_base"/>
    <child link="right_wheel"/>
    <axis xyz="1.0 0.0 0.0"/>
  </joint>

  <joint name="caster1_fix_joint" type="fixed">
    <origin xyz="0.144 0.090 0.01125" rpy="0 0 0"/>
    <parent link="slam_base"/>
    <child link="lf_caster"/>
  </joint>

  <joint name="caster2_fix_joint" type="fixed">
    <origin xyz="0.144 -0.090 0.01125" rpy="0 0 0"/>
    <parent link="slam_base"/>
    <child link="rf_caster"/>
  </joint>

  <joint name="caster3_fix_joint" type="fixed">
    <origin xyz="-0.144 0.100 0.01125" rpy="0 0 0"/>
    <parent link="slam_base"/>
    <child link="lb_caster"/>
  </joint>

  <joint name="caster4_fix_joint" type="fixed">
    <origin xyz="-0.144 -0.100 0.01125" rpy="0 0 0"/>
    <parent link="slam_base"/>
    <child link="rb_caster"/>
  </joint>

</robot>
