<?xml version="1.0" ?>
<robot name="slamtec" xmlns:xacro="http://www.ros.org/wiki/xacro">


  <xacro:property name="mesh_path" value="package://kcare_description/meshes/"/>

  <xacro:common_link
    name="slam_base"
    mesh_file="${mesh_path}slamware/base_link.stl"
  />

  <xacro:common_link
    name="left_wheel"
    mesh_file="${mesh_path}slamware/slam_wheel.stl"
    material="black"
  />

  <xacro:common_link
    name="right_wheel"
    mesh_file="${mesh_path}slamware/slam_wheel.stl"
    material="black"
  />

  <xacro:common_link
    name="lf_caster"
    mesh_file="${mesh_path}slamware/caster.stl"
    material="black"
  />

  <xacro:common_link
    name="rf_caster"
     mesh_file="${mesh_path}slamware/caster.stl"
    material="black"
  />

  <xacro:common_link
    name="lb_caster"
    mesh_file="${mesh_path}slamware/caster.stl"
    material="black"
  />

  <xacro:common_link
    name="rb_caster"
    mesh_file="${mesh_path}slamware/caster.stl"
    material="black"
  />

  <link name="elevation_base">
  </link>

  <joint name="left_wheel_joint" type="continuous">
    <origin xyz="0.0 0.16885 0.0" rpy="0 0 -1.5708"/>
    <parent link="slam_base"/>
    <child link="left_wheel"/>
    <axis xyz="-1.0 0.0 0.0"/>
  </joint>

  <joint name="right_wheel_joint" type="continuous">
    <origin xyz="0.0 -0.16885 0.0" rpy="0 0 1.5708"/>
    <parent link="slam_base"/>
    <child link="right_wheel"/>
    <axis xyz="1.0 0.0 0.0"/>
  </joint>

  <joint name="caster1_fix_joint" type="fixed">
    <origin xyz="0.144 0.090 0.01125" rpy="0 0 0"/>
    <parent link="slam_base"/>
    <child link="lf_caster"/>
  </joint>

  <joint name="caster2_fix_joint" type="fixed">
    <origin xyz="0.144 -0.090 0.01125" rpy="0 0 0"/>
    <parent link="slam_base"/>
    <child link="rf_caster"/>
  </joint>

  <joint name="caster3_fix_joint" type="fixed">
    <origin xyz="-0.144 0.100 0.01125" rpy="0 0 0"/>
    <parent link="slam_base"/>
    <child link="lb_caster"/>
  </joint>

  <joint name="caster4_fix_joint" type="fixed">
    <origin xyz="-0.144 -0.100 0.01125" rpy="0 0 0"/>
    <parent link="slam_base"/>
    <child link="rb_caster"/>
  </joint>

  <joint name="slam_to_elev_fix_joint" type="fixed">
    <origin xyz="0.0 0.0 0.362985" rpy="0 0 0"/>
    <parent link="slam_base"/>
    <child link="elevation_base"/>
  </joint>

</robot>
